<?xml version="1.0" encoding="utf-8"?>
<robot name="fanuc_m20ia_35m" xmlns:xacro="http://www.ros.org/wiki/xacro">
    <!--************************************************WORLD_LINK********************************************-->

    <xacro:include filename="$(find acg_resources_fanuc_m20ia_35m_description)/urdf/inertial.xacro"/>
    <link name ="world">
    </link>

    <!--************************************************SLIDER********************************************-->

    <link name ="slider_tool">
        <visual>
            <origin rpy="3.14159265359 -1.57079632679 -1.57079632679" xyz="0.002 -0.135 -0.155"/>
            <geometry>
                <mesh filename="package://acg_resources_fanuc_m20ia_35m_description/meshes/visual/slide.dae" />
            </geometry>
        </visual>
        <collision>
            <origin rpy="3.14159265359 -1.57079632679 0" xyz="0.002 -0.135 -0.155"/>
            <geometry>
                <mesh filename="package://acg_resources_fanuc_m20ia_35m_description/meshes/collision/slide.stl" />
            </geometry>
        </collision>
        <xacro:inertial_props name="slide" />

    </link>
    
    <joint name="joint_world_to_slider" type="prismatic">
        <origin rpy="0 -1.57 0" xyz="0 0 0"/>
        <parent link="world"/>
        <child link="slider_tool"/>
        <axis xyz="0 0 1"/>
        <limit effort="10000" lower="-2.1" upper="2.1" velocity="9.6" /> 
        <dynamics damping="1" friction="1"/>

    </joint>

    <!--************************************************LINK_0********************************************-->
    
    <link name ="fanuc_m20ia_35m_link_0">
        <visual>
            <origin rpy="-1.570796326790 0 0" xyz="0 0 0"/>
            <geometry>
                <mesh filename="package://acg_resources_fanuc_m20ia_35m_description/meshes/visual/link_0.dae" />
            </geometry>
        </visual>
        <collision>
            <origin rpy="0 0 0" xyz="0 0 0"/>

            <geometry>
                <mesh filename="package://acg_resources_fanuc_m20ia_35m_description/meshes/collision/link_0.stl" />
            </geometry>
        </collision>
        <xacro:inertial_props name="link_0" />

    </link>

    <joint name="fanuc_m20ia_35m_joint_slider_to_link_0" type="fixed">
        <origin rpy="1.57 0 1.57" xyz="0.55 0 0"/>
        <parent link="slider_tool"/>
        <child link="fanuc_m20ia_35m_link_0"/>
    </joint>

    <!--************************************************LINK_1********************************************-->
    
    <link name ="fanuc_m20ia_35m_link_1">

        <visual>
            <origin rpy="-1.57079632679 0 0" xyz="0 0 0"/>

            <geometry>
                <mesh filename="package://acg_resources_fanuc_m20ia_35m_description/meshes/visual/link_1.dae" />
            </geometry>
        </visual>
        <collision>
            <origin rpy="0 0 0" xyz="0 0 0"/>

            <geometry>
                <mesh filename="package://acg_resources_fanuc_m20ia_35m_description/meshes/collision/link_1.stl" />
            </geometry>
        </collision>
        <xacro:inertial_props name="link_1" />

    </link>

    <joint name="fanuc_m20ia_35m_joint1" type="revolute">
        <origin rpy="0 0 0" xyz="0 0 0"/>
        <parent link="fanuc_m20ia_35m_link_0"/>
        <child link="fanuc_m20ia_35m_link_1"/>
        <axis xyz="0 0 1"/>
        <limit effort="10000" lower="-3.228859" upper="3.228859" velocity="3.14" />
         <dynamics damping="1.0640" friction="1.0066"/>
    </joint>

    <!--************************************************LINK_2********************************************-->

    <link name = "fanuc_m20ia_35m_link_2">
        <visual>
            <origin rpy="-3.14159265359 0 0" xyz="-0.15 -0.525 0"/>
            <geometry>
                <mesh filename="package://acg_resources_fanuc_m20ia_35m_description/meshes/visual/link_2.dae" />
            </geometry>
        </visual>
        <collision>
            <origin rpy="-1.57079632679 0 0" xyz="-0.15 -0.525 0"/>

            <geometry>
                <mesh filename="package://acg_resources_fanuc_m20ia_35m_description/meshes/collision/link_2.stl" />
            </geometry>
        </collision>
        <xacro:inertial_props name="link_2" />

    </link>

    <joint name="fanuc_m20ia_35m_joint2" type="revolute">
        <origin rpy="1.57079632679 0 0" xyz="0.15 0 0.525"/>
        <parent link="fanuc_m20ia_35m_link_1"/>
        <child link="fanuc_m20ia_35m_link_2"/>
        <axis xyz="0 0 1"/>
        <limit effort="10000" lower="-2.7911" upper="1.7444" velocity="3.14" />
        <dynamics damping="0.9944" friction="0.9563"/>

    </joint>



    <!--************************************************LINK_3********************************************-->

    <link name = "fanuc_m20ia_35m_link_3">  
        <visual>
            <origin rpy="-3.14159265359 0 -1.57079632679" xyz="-1.315 0.15 0"/>

            <geometry>
                <mesh filename="package://acg_resources_fanuc_m20ia_35m_description/meshes/visual/link_3.dae" />
            </geometry>
        </visual>
        <collision>
            <origin rpy="-1.57079632679 0 -1.57079632679" xyz="-1.315 0.15 0"/>

            <geometry>
                <mesh filename="package://acg_resources_fanuc_m20ia_35m_description/meshes/collision/link_3.stl" />
            </geometry>
        </collision>
        <xacro:inertial_props name="link_3" />

    </link> 

     
    <joint name="fanuc_m20ia_35m_joint3" type="revolute">
        <origin rpy="0 0 1.57" xyz="0 0.79 0"/>
        <parent link="fanuc_m20ia_35m_link_2"/>
        <child link="fanuc_m20ia_35m_link_3"/>
        <axis xyz="0 0 1"/>
        <limit effort="10000" lower="-4.8171" upper="3.2225" velocity="3.49" />
        <dynamics damping="0.6796" friction="0.8120"/>

    </joint>



    <!--************************************************LINK_4********************************************-->

    <link name = "fanuc_m20ia_35m_link_4">   
        <visual>
            <origin rpy="-1.57079632679 -1.57079632679 3.14 " xyz="-1.465 0 -0.15"/>

            <geometry>
                <mesh filename="package://acg_resources_fanuc_m20ia_35m_description/meshes/visual/link_4.dae" />
            </geometry>
        </visual>
        <collision>
            <origin rpy="0 -1.57079632679 3.14 " xyz="-1.465 0 -0.15"/>

            <geometry>
                <mesh filename="package://acg_resources_fanuc_m20ia_35m_description/meshes/collision/link_4.stl" />
            </geometry>
        </collision>
        <xacro:inertial_props name="link_4" />

    </link>

    <joint name="fanuc_m20ia_35m_joint4" type="revolute">
        <origin rpy="1.57079632679 0 0" xyz="0.15 0 0"/>
        <parent link="fanuc_m20ia_35m_link_3"/>
        <child link="fanuc_m20ia_35m_link_4"/>
        <axis xyz="0 0 1"/>
        <limit effort="110" lower="-3.49" upper="3.49" velocity="6.11" />
        <dynamics damping="0.3159" friction="0.1767"/>

    </joint>

    <!--************************************************LINK_5********************************************-->

    <link name = "fanuc_m20ia_35m_link_5">  
        <visual>
            <origin rpy="0 0 -1.57079632679" xyz="1.465 1.01 0"/>

            <geometry>
                <mesh filename="package://acg_resources_fanuc_m20ia_35m_description/meshes/visual/link_5.dae" />
            </geometry>
        </visual>
        <collision>
            <origin rpy="1.57079632679 0 -1.57079632679" xyz="1.465 1.01 0"/>

            <geometry>
                <mesh filename="package://acg_resources_fanuc_m20ia_35m_description/meshes/collision/link_5.stl" />
            </geometry>
        </collision>
        <xacro:inertial_props name="link_5" />

    </link>

    <joint name="fanuc_m20ia_35m_joint5" type="revolute">
        <origin rpy="-1.57079632679 0 0" xyz="0 0 0.86"/>
        <parent link="fanuc_m20ia_35m_link_4"/>
        <child link="fanuc_m20ia_35m_link_5"/>
        <axis xyz="0 0 1"/>
        <limit effort="110" lower="-2.445" upper="2.445" velocity="6.11" />
        <dynamics damping="0.2244" friction="0.1924"/>

    </joint>

    <!--************************************************LINK_6********************************************-->

    <link name = "fanuc_m20ia_35m_link_6">  
        <visual>
            <origin rpy="-1.57 0 0" xyz="0 0 0.1"/>

            <geometry>
                <mesh filename="package://acg_resources_fanuc_m20ia_35m_description/meshes/visual/link_6.dae" />
            </geometry>
        </visual>
        <collision>
            <origin rpy="0 0 0" xyz="0 0 0.1"/>

            <geometry>
                <mesh filename="package://acg_resources_fanuc_m20ia_35m_description/meshes/collision/link_6.stl" />
            </geometry>
        </collision>
        <xacro:inertial_props name="link_6" />

    </link>

    <joint name="fanuc_m20ia_35m_joint6" type="revolute">
        <origin rpy="1.57079632679 0 0" xyz="0 0 0"/>
        <parent link="fanuc_m20ia_35m_link_5"/>
        <child link="fanuc_m20ia_35m_link_6"/>
        <axis xyz="0 0 1"/>
        <limit effort="60" lower="-7.885" upper="7.885" velocity="6.98" />
        <dynamics damping="0.2358" friction="0.2453"/>

    </joint>

    <!--************************************************LINK_7********************************************-->
  
    <link name = "drilling_tool">
        <visual>
            <origin rpy="3.14 0 -1.57" xyz="0.069 0.019 -0.246"/> 

            <geometry>
                <mesh filename="package://acg_resources_fanuc_m20ia_35m_description/meshes/visual/drilling_tool.dae" />
            </geometry>
        </visual>
        <collision>
            <origin rpy="-1.544 0 -1.543" xyz="-1.263008 -0.01635 -1.447666"/> 
            <geometry>
                <mesh filename="package://acg_resources_fanuc_m20ia_35m_description/meshes/collision/drilling_tool.stl" /> 
            </geometry>
        </collision>
        <xacro:inertial_props name="drilling_tool" />

    </link>
 
    <joint name="fanuc_m20ia_35m_joint_link6_to_drilling_tool" type="fixed">
        <origin rpy="0 0 0" xyz="-0.204 0.006 0.396"/>
        <parent link="fanuc_m20ia_35m_link_6"/>
        <child link="drilling_tool"/>
    </joint>


    <link name = "fastening_tool">
    </link>

     <joint name="fanuc_m20ia_35m_link6_to_fastening_tool" type="fixed">
        <origin rpy="0 0 0" xyz="-0.2 0.12 0.338"/>
        <parent link="fanuc_m20ia_35m_link_6"/>
        <child link="fastening_tool"/>

    </joint>

     
</robot>
